{
	"cve": {
		"CVE_data_meta": {
			"ASSIGNER": "psirt@us.ibm.com",
			"ID": "CVE-2020-4388"
		},
		"data_format": "MITRE",
		"data_type": "CVE",
		"data_version": "4.0",
		"description": {
			"description_data": [
				{
					"lang": "en",
					"value": "IBM Cognos Analytics 11.0 and 11.1 could be vulnerable to a denial of service attack by failing to catch exceptions in a servlet also exposing debug information could also be used in future attacks. IBM X-Force ID: 179270."
				}
			]
		},
		"problemtype": {
			"problemtype_data": [
				{
					"description": [
						{
							"lang": "en",
							"value": "CWE-755"
						}
					]
				}
			]
		},
		"references": {
			"reference_data": [
				{
					"name": "ibm-cognos-cve20204388-dos (179270)",
					"refsource": "XF",
					"tags": [
						"VDB Entry",
						"Vendor Advisory"
					],
					"url": "https://exchange.xforce.ibmcloud.com/vulnerabilities/179270"
				},
				{
					"name": "https://www.ibm.com/support/pages/node/6346922",
					"refsource": "CONFIRM",
					"tags": [
						"Patch",
						"Vendor Advisory"
					],
					"url": "https://www.ibm.com/support/pages/node/6346922"
				}
			]
		}
	},
	"impact": {
		"baseMetricV2": {
			"cvssV2": {
				"accessComplexity": "LOW",
				"accessVector": "NETWORK",
				"authentication": "NONE",
				"availabilityImpact": "PARTIAL",
				"baseScore": 6.4,
				"confidentialityImpact": "PARTIAL",
				"integrityImpact": "NONE",
				"vectorString": "AV:N/AC:L/Au:N/C:P/I:N/A:P",
				"version": "2.0"
			},
			"exploitabilityScore": 10,
			"impactScore": 4.9,
			"severity": "MEDIUM"
		},
		"baseMetricV3": {
			"cvssV3": {
				"attackComplexity": "LOW",
				"attackVector": "NETWORK",
				"availabilityImpact": "HIGH",
				"baseScore": 8.2,
				"baseSeverity": "HIGH",
				"confidentialityImpact": "LOW",
				"integrityImpact": "NONE",
				"privilegesRequired": "NONE",
				"scope": "UNCHANGED",
				"userInteraction": "NONE",
				"vectorString": "CVSS:3.1/AV:N/AC:L/PR:N/UI:N/S:U/C:L/I:N/A:H",
				"version": "3.1"
			},
			"exploitabilityScore": 3.9,
			"impactScore": 4.2
		}
	},
	"configurations": {
		"CVE_data_version": "4.0",
		"nodes": [
			{
				"cpe_match": [
					{
						"cpe23Uri": "cpe:2.3:a:ibm:cognos_analytics:11.0.13:-:*:*:*:*:*:*",
						"vulnerable": true
					},
					{
						"cpe23Uri": "cpe:2.3:a:ibm:cognos_analytics:11.0.13:fixpack1:*:*:*:*:*:*",
						"vulnerable": true
					},
					{
						"cpe23Uri": "cpe:2.3:a:ibm:cognos_analytics:11.0.13:fixpack2:*:*:*:*:*:*",
						"vulnerable": true
					},
					{
						"cpe23Uri": "cpe:2.3:a:ibm:cognos_analytics:*:*:*:*:*:*:*:*",
						"versionEndIncluding": "11.1.7",
						"versionStartIncluding": "11.1.0",
						"vulnerable": true
					},
					{
						"cpe23Uri": "cpe:2.3:a:ibm:cognos_analytics:*:*:*:*:*:*:*:*",
						"versionEndExcluding": "11.0.13",
						"versionStartIncluding": "11.0.0",
						"vulnerable": true
					}
				],
				"operator": "OR"
			}
		]
	},
	"lastModifiedDate": "2020-10-14T13:25Z",
	"publishedDate": "2020-10-12T14:15Z"
}
